Traceback (most recent call last):
  File "/usr/local/lib/python3.10/dist-packages/jupyter_cache/executors/utils.py", line 58, in single_nb_execution
    executenb(
  File "/usr/local/lib/python3.10/dist-packages/nbclient/client.py", line 1305, in execute
    return NotebookClient(nb=nb, resources=resources, km=km, **kwargs).execute()
  File "/usr/local/lib/python3.10/dist-packages/jupyter_core/utils/__init__.py", line 166, in wrapped
    return loop.run_until_complete(inner)
  File "/usr/lib/python3.10/asyncio/base_events.py", line 649, in run_until_complete
    return future.result()
  File "/usr/local/lib/python3.10/dist-packages/nbclient/client.py", line 705, in async_execute
    await self.async_execute_cell(
  File "/usr/local/lib/python3.10/dist-packages/nbclient/client.py", line 1058, in async_execute_cell
    await self._check_raise_for_error(cell, cell_index, exec_reply)
  File "/usr/local/lib/python3.10/dist-packages/nbclient/client.py", line 914, in _check_raise_for_error
    raise CellExecutionError.from_cell_and_msg(cell, exec_reply_content)
nbclient.exceptions.CellExecutionError: An error occurred while executing the following cell:
------------------
conn = psycopg2.connect(
    dbname="prosain20041110007",
    user="postgres",
    password="2020",
    host="localhost",
    port="5432"
)

# Create a cursor object
cur = conn.cursor()

# Execute a SQL query
cur.execute("SELECT sepallengthcm FROM iris;")

# Fetch the results
results = cur.fetchall()

# Print the results
for row in results:
    print(row)

# Close the cursor and connection objects when you're done
cur.close()
conn.close()


------------------


[0;31m[0m
[0;31mOperationalError[0mTraceback (most recent call last)
[0;32m<ipython-input-5-c22ac8d2d9c6>[0m in [0;36m<cell line: 1>[0;34m()[0m
[0;32m----> 1[0;31m conn = psycopg2.connect(
[0m[1;32m      2[0m     [0mdbname[0m[0;34m=[0m[0;34m"prosain20041110007"[0m[0;34m,[0m[0;34m[0m[0;34m[0m[0m
[1;32m      3[0m     [0muser[0m[0;34m=[0m[0;34m"postgres"[0m[0;34m,[0m[0;34m[0m[0;34m[0m[0m
[1;32m      4[0m     [0mpassword[0m[0;34m=[0m[0;34m"2020"[0m[0;34m,[0m[0;34m[0m[0;34m[0m[0m
[1;32m      5[0m     [0mhost[0m[0;34m=[0m[0;34m"localhost"[0m[0;34m,[0m[0;34m[0m[0;34m[0m[0m

[0;32m/usr/local/lib/python3.10/dist-packages/psycopg2/__init__.py[0m in [0;36mconnect[0;34m(dsn, connection_factory, cursor_factory, **kwargs)[0m
[1;32m    120[0m [0;34m[0m[0m
[1;32m    121[0m     [0mdsn[0m [0;34m=[0m [0m_ext[0m[0;34m.[0m[0mmake_dsn[0m[0;34m([0m[0mdsn[0m[0;34m,[0m [0;34m**[0m[0mkwargs[0m[0;34m)[0m[0;34m[0m[0;34m[0m[0m
[0;32m--> 122[0;31m     [0mconn[0m [0;34m=[0m [0m_connect[0m[0;34m([0m[0mdsn[0m[0;34m,[0m [0mconnection_factory[0m[0;34m=[0m[0mconnection_factory[0m[0;34m,[0m [0;34m**[0m[0mkwasync[0m[0;34m)[0m[0;34m[0m[0;34m[0m[0m
[0m[1;32m    123[0m     [0;32mif[0m [0mcursor_factory[0m [0;32mis[0m [0;32mnot[0m [0;32mNone[0m[0;34m:[0m[0;34m[0m[0;34m[0m[0m
[1;32m    124[0m         [0mconn[0m[0;34m.[0m[0mcursor_factory[0m [0;34m=[0m [0mcursor_factory[0m[0;34m[0m[0;34m[0m[0m

[0;31mOperationalError[0m: connection to server at "localhost" (127.0.0.1), port 5432 failed: Connection refused
	Is the server running on that host and accepting TCP/IP connections?
connection to server at "localhost" (::1), port 5432 failed: Cannot assign requested address
	Is the server running on that host and accepting TCP/IP connections?


